[2025-08-24T19:16:33.473+0000] {taskinstance.py:1956} INFO - Dependencies all met for dep_context=non-requeueable deps ti=<TaskInstance: weather_etl.transform_weather manual__2025-08-24T19:11:29.085129+00:00 [queued]>
[2025-08-24T19:16:33.481+0000] {taskinstance.py:1956} INFO - Dependencies all met for dep_context=requeueable deps ti=<TaskInstance: weather_etl.transform_weather manual__2025-08-24T19:11:29.085129+00:00 [queued]>
[2025-08-24T19:16:33.483+0000] {taskinstance.py:2170} INFO - Starting attempt 2 of 2
[2025-08-24T19:16:33.496+0000] {taskinstance.py:2191} INFO - Executing <Task(PythonOperator): transform_weather> on 2025-08-24 19:11:29.085129+00:00
[2025-08-24T19:16:33.501+0000] {standard_task_runner.py:60} INFO - Started process 266 to run task
[2025-08-24T19:16:33.503+0000] {standard_task_runner.py:87} INFO - Running: ['***', 'tasks', 'run', 'weather_etl', 'transform_weather', 'manual__2025-08-24T19:11:29.085129+00:00', '--job-id', '8', '--raw', '--subdir', 'DAGS_FOLDER/weather_etl.py', '--cfg-path', '/tmp/tmph_4y5my9']
[2025-08-24T19:16:33.505+0000] {standard_task_runner.py:88} INFO - Job 8: Subtask transform_weather
[2025-08-24T19:16:33.599+0000] {task_command.py:423} INFO - Running <TaskInstance: weather_etl.transform_weather manual__2025-08-24T19:11:29.085129+00:00 [running]> on host 7b1c3b0dd09a
[2025-08-24T19:16:33.782+0000] {taskinstance.py:2480} INFO - Exporting env vars: AIRFLOW_CTX_DAG_OWNER='***' AIRFLOW_CTX_DAG_ID='weather_etl' AIRFLOW_CTX_TASK_ID='transform_weather' AIRFLOW_CTX_EXECUTION_DATE='2025-08-24T19:11:29.085129+00:00' AIRFLOW_CTX_TRY_NUMBER='2' AIRFLOW_CTX_DAG_RUN_ID='manual__2025-08-24T19:11:29.085129+00:00'
[2025-08-24T19:16:33.792+0000] {taskinstance.py:2698} ERROR - Task failed with exception
Traceback (most recent call last):
  File "/home/airflow/.local/lib/python3.8/site-packages/airflow/models/taskinstance.py", line 433, in _execute_task
    result = execute_callable(context=context, **execute_callable_kwargs)
  File "/home/airflow/.local/lib/python3.8/site-packages/airflow/operators/python.py", line 199, in execute
    return_value = self.execute_callable()
  File "/home/airflow/.local/lib/python3.8/site-packages/airflow/operators/python.py", line 216, in execute_callable
    return self.python_callable(*self.op_args, **self.op_kwargs)
  File "/opt/airflow/dags/weather_etl.py", line 37, in transform_weather
    "city": data["name"],
KeyError: 'name'
[2025-08-24T19:16:33.808+0000] {taskinstance.py:1138} INFO - Marking task as FAILED. dag_id=weather_etl, task_id=transform_weather, execution_date=20250824T191129, start_date=20250824T191633, end_date=20250824T191633
[2025-08-24T19:16:33.818+0000] {standard_task_runner.py:107} ERROR - Failed to execute job 8 for task transform_weather ('name'; 266)
[2025-08-24T19:16:33.839+0000] {local_task_job_runner.py:234} INFO - Task exited with return code 1
[2025-08-24T19:16:33.872+0000] {taskinstance.py:3280} INFO - 0 downstream tasks scheduled from follow-on schedule check
