[2025-08-24T20:00:06.235+0000] {taskinstance.py:1956} INFO - Dependencies all met for dep_context=non-requeueable deps ti=<TaskInstance: weather_etl.load_raw_london scheduled__2025-08-24T19:00:00+00:00 [queued]>
[2025-08-24T20:00:06.246+0000] {taskinstance.py:1956} INFO - Dependencies all met for dep_context=requeueable deps ti=<TaskInstance: weather_etl.load_raw_london scheduled__2025-08-24T19:00:00+00:00 [queued]>
[2025-08-24T20:00:06.247+0000] {taskinstance.py:2170} INFO - Starting attempt 1 of 2
[2025-08-24T20:00:06.269+0000] {taskinstance.py:2191} INFO - Executing <Task(PythonOperator): load_raw_london> on 2025-08-24 19:00:00+00:00
[2025-08-24T20:00:06.275+0000] {standard_task_runner.py:60} INFO - Started process 200 to run task
[2025-08-24T20:00:06.280+0000] {standard_task_runner.py:87} INFO - Running: ['***', 'tasks', 'run', 'weather_etl', 'load_raw_london', 'scheduled__2025-08-24T19:00:00+00:00', '--job-id', '27', '--raw', '--subdir', 'DAGS_FOLDER/weather_etl.py', '--cfg-path', '/tmp/tmp2u1lsf88']
[2025-08-24T20:00:06.283+0000] {standard_task_runner.py:88} INFO - Job 27: Subtask load_raw_london
[2025-08-24T20:00:06.383+0000] {task_command.py:423} INFO - Running <TaskInstance: weather_etl.load_raw_london scheduled__2025-08-24T19:00:00+00:00 [running]> on host 7b1c3b0dd09a
[2025-08-24T20:00:06.491+0000] {taskinstance.py:2480} INFO - Exporting env vars: AIRFLOW_CTX_DAG_OWNER='***' AIRFLOW_CTX_DAG_ID='weather_etl' AIRFLOW_CTX_TASK_ID='load_raw_london' AIRFLOW_CTX_EXECUTION_DATE='2025-08-24T19:00:00+00:00' AIRFLOW_CTX_TRY_NUMBER='1' AIRFLOW_CTX_DAG_RUN_ID='scheduled__2025-08-24T19:00:00+00:00'
[2025-08-24T20:00:06.514+0000] {taskinstance.py:2698} ERROR - Task failed with exception
Traceback (most recent call last):
  File "/home/airflow/.local/lib/python3.8/site-packages/airflow/models/taskinstance.py", line 433, in _execute_task
    result = execute_callable(context=context, **execute_callable_kwargs)
  File "/home/airflow/.local/lib/python3.8/site-packages/airflow/operators/python.py", line 199, in execute
    return_value = self.execute_callable()
  File "/home/airflow/.local/lib/python3.8/site-packages/airflow/operators/python.py", line 216, in execute_callable
    return self.python_callable(*self.op_args, **self.op_kwargs)
  File "/opt/airflow/dags/weather_etl.py", line 56, in load_raw_weather
    cur.execute("""
psycopg2.errors.UniqueViolation: duplicate key value violates unique constraint "pg_type_typname_nsp_index"
DETAIL:  Key (typname, typnamespace)=(raw_weather, 2200) already exists.

[2025-08-24T20:00:06.531+0000] {taskinstance.py:1138} INFO - Marking task as UP_FOR_RETRY. dag_id=weather_etl, task_id=load_raw_london, execution_date=20250824T190000, start_date=20250824T200006, end_date=20250824T200006
[2025-08-24T20:00:06.545+0000] {standard_task_runner.py:107} ERROR - Failed to execute job 27 for task load_raw_london (duplicate key value violates unique constraint "pg_type_typname_nsp_index"
DETAIL:  Key (typname, typnamespace)=(raw_weather, 2200) already exists.
; 200)
[2025-08-24T20:00:06.575+0000] {local_task_job_runner.py:234} INFO - Task exited with return code 1
[2025-08-24T20:00:06.605+0000] {taskinstance.py:3280} INFO - 0 downstream tasks scheduled from follow-on schedule check
