[2025-08-24T20:05:44.497+0000] {taskinstance.py:1956} INFO - Dependencies all met for dep_context=non-requeueable deps ti=<TaskInstance: weather_etl.transform_mumbai manual__2025-08-24T20:00:40.718194+00:00 [queued]>
[2025-08-24T20:05:44.508+0000] {taskinstance.py:1956} INFO - Dependencies all met for dep_context=requeueable deps ti=<TaskInstance: weather_etl.transform_mumbai manual__2025-08-24T20:00:40.718194+00:00 [queued]>
[2025-08-24T20:05:44.509+0000] {taskinstance.py:2170} INFO - Starting attempt 2 of 2
[2025-08-24T20:05:44.524+0000] {taskinstance.py:2191} INFO - Executing <Task(PythonOperator): transform_mumbai> on 2025-08-24 20:00:40.718194+00:00
[2025-08-24T20:05:44.531+0000] {standard_task_runner.py:60} INFO - Started process 268 to run task
[2025-08-24T20:05:44.535+0000] {standard_task_runner.py:87} INFO - Running: ['***', 'tasks', 'run', 'weather_etl', 'transform_mumbai', 'manual__2025-08-24T20:00:40.718194+00:00', '--job-id', '53', '--raw', '--subdir', 'DAGS_FOLDER/weather_etl.py', '--cfg-path', '/tmp/tmpll4b3h9y']
[2025-08-24T20:05:44.538+0000] {standard_task_runner.py:88} INFO - Job 53: Subtask transform_mumbai
[2025-08-24T20:05:44.627+0000] {task_command.py:423} INFO - Running <TaskInstance: weather_etl.transform_mumbai manual__2025-08-24T20:00:40.718194+00:00 [running]> on host 7b1c3b0dd09a
[2025-08-24T20:05:44.706+0000] {taskinstance.py:2480} INFO - Exporting env vars: AIRFLOW_CTX_DAG_OWNER='***' AIRFLOW_CTX_DAG_ID='weather_etl' AIRFLOW_CTX_TASK_ID='transform_mumbai' AIRFLOW_CTX_EXECUTION_DATE='2025-08-24T20:00:40.718194+00:00' AIRFLOW_CTX_TRY_NUMBER='2' AIRFLOW_CTX_DAG_RUN_ID='manual__2025-08-24T20:00:40.718194+00:00'
[2025-08-24T20:05:44.720+0000] {taskinstance.py:2698} ERROR - Task failed with exception
Traceback (most recent call last):
  File "/home/airflow/.local/lib/python3.8/site-packages/airflow/models/taskinstance.py", line 433, in _execute_task
    result = execute_callable(context=context, **execute_callable_kwargs)
  File "/home/airflow/.local/lib/python3.8/site-packages/airflow/operators/python.py", line 199, in execute
    return_value = self.execute_callable()
  File "/home/airflow/.local/lib/python3.8/site-packages/airflow/operators/python.py", line 216, in execute_callable
    return self.python_callable(*self.op_args, **self.op_kwargs)
  File "/opt/airflow/dags/weather_etl.py", line 74, in transform_and_load
    raise ValueError(f"Missing expected keys in API response for {city}: {data}")
ValueError: Missing expected keys in API response for Mumbai: {'cod': 401, 'message': 'Invalid API key. Please see https://openweathermap.org/faq#error401 for more info.'}
[2025-08-24T20:05:44.738+0000] {taskinstance.py:1138} INFO - Marking task as FAILED. dag_id=weather_etl, task_id=transform_mumbai, execution_date=20250824T200040, start_date=20250824T200544, end_date=20250824T200544
[2025-08-24T20:05:44.752+0000] {standard_task_runner.py:107} ERROR - Failed to execute job 53 for task transform_mumbai (Missing expected keys in API response for Mumbai: {'cod': 401, 'message': 'Invalid API key. Please see https://openweathermap.org/faq#error401 for more info.'}; 268)
[2025-08-24T20:05:44.787+0000] {local_task_job_runner.py:234} INFO - Task exited with return code 1
[2025-08-24T20:05:44.805+0000] {taskinstance.py:3280} INFO - 0 downstream tasks scheduled from follow-on schedule check
