[2025-08-24T20:10:38.150+0000] {taskinstance.py:1956} INFO - Dependencies all met for dep_context=non-requeueable deps ti=<TaskInstance: weather_etl.transform_mumbai manual__2025-08-24T20:10:34.878611+00:00 [queued]>
[2025-08-24T20:10:38.166+0000] {taskinstance.py:1956} INFO - Dependencies all met for dep_context=requeueable deps ti=<TaskInstance: weather_etl.transform_mumbai manual__2025-08-24T20:10:34.878611+00:00 [queued]>
[2025-08-24T20:10:38.167+0000] {taskinstance.py:2170} INFO - Starting attempt 1 of 2
[2025-08-24T20:10:38.191+0000] {taskinstance.py:2191} INFO - Executing <Task(PythonOperator): transform_mumbai> on 2025-08-24 20:10:34.878611+00:00
[2025-08-24T20:10:38.202+0000] {standard_task_runner.py:60} INFO - Started process 219 to run task
[2025-08-24T20:10:38.207+0000] {standard_task_runner.py:87} INFO - Running: ['***', 'tasks', 'run', 'weather_etl', 'transform_mumbai', 'manual__2025-08-24T20:10:34.878611+00:00', '--job-id', '67', '--raw', '--subdir', 'DAGS_FOLDER/weather_etl.py', '--cfg-path', '/tmp/tmp1cdem0yu']
[2025-08-24T20:10:38.210+0000] {standard_task_runner.py:88} INFO - Job 67: Subtask transform_mumbai
[2025-08-24T20:10:38.306+0000] {task_command.py:423} INFO - Running <TaskInstance: weather_etl.transform_mumbai manual__2025-08-24T20:10:34.878611+00:00 [running]> on host 6db65bba76ed
[2025-08-24T20:10:38.402+0000] {taskinstance.py:2480} INFO - Exporting env vars: AIRFLOW_CTX_DAG_OWNER='***' AIRFLOW_CTX_DAG_ID='weather_etl' AIRFLOW_CTX_TASK_ID='transform_mumbai' AIRFLOW_CTX_EXECUTION_DATE='2025-08-24T20:10:34.878611+00:00' AIRFLOW_CTX_TRY_NUMBER='1' AIRFLOW_CTX_DAG_RUN_ID='manual__2025-08-24T20:10:34.878611+00:00'
[2025-08-24T20:10:38.448+0000] {taskinstance.py:2698} ERROR - Task failed with exception
Traceback (most recent call last):
  File "/home/airflow/.local/lib/python3.8/site-packages/airflow/models/taskinstance.py", line 433, in _execute_task
    result = execute_callable(context=context, **execute_callable_kwargs)
  File "/home/airflow/.local/lib/python3.8/site-packages/airflow/operators/python.py", line 199, in execute
    return_value = self.execute_callable()
  File "/home/airflow/.local/lib/python3.8/site-packages/airflow/operators/python.py", line 216, in execute_callable
    return self.python_callable(*self.op_args, **self.op_kwargs)
  File "/opt/airflow/dags/weather_etl.py", line 92, in transform_and_load
    cur.execute("""
psycopg2.errors.UniqueViolation: duplicate key value violates unique constraint "pg_type_typname_nsp_index"
DETAIL:  Key (typname, typnamespace)=(weather, 2200) already exists.

[2025-08-24T20:10:38.466+0000] {taskinstance.py:1138} INFO - Marking task as UP_FOR_RETRY. dag_id=weather_etl, task_id=transform_mumbai, execution_date=20250824T201034, start_date=20250824T201038, end_date=20250824T201038
[2025-08-24T20:10:38.483+0000] {standard_task_runner.py:107} ERROR - Failed to execute job 67 for task transform_mumbai (duplicate key value violates unique constraint "pg_type_typname_nsp_index"
DETAIL:  Key (typname, typnamespace)=(weather, 2200) already exists.
; 219)
[2025-08-24T20:10:38.506+0000] {local_task_job_runner.py:234} INFO - Task exited with return code 1
[2025-08-24T20:10:38.550+0000] {taskinstance.py:3280} INFO - 0 downstream tasks scheduled from follow-on schedule check
