[2025-08-24T20:00:06.936+0000] {taskinstance.py:1956} INFO - Dependencies all met for dep_context=non-requeueable deps ti=<TaskInstance: weather_etl.transform_new_york scheduled__2025-08-24T19:00:00+00:00 [queued]>
[2025-08-24T20:00:06.945+0000] {taskinstance.py:1956} INFO - Dependencies all met for dep_context=requeueable deps ti=<TaskInstance: weather_etl.transform_new_york scheduled__2025-08-24T19:00:00+00:00 [queued]>
[2025-08-24T20:00:06.946+0000] {taskinstance.py:2170} INFO - Starting attempt 1 of 2
[2025-08-24T20:00:06.960+0000] {taskinstance.py:2191} INFO - Executing <Task(PythonOperator): transform_new_york> on 2025-08-24 19:00:00+00:00
[2025-08-24T20:00:06.965+0000] {standard_task_runner.py:60} INFO - Started process 203 to run task
[2025-08-24T20:00:06.969+0000] {standard_task_runner.py:87} INFO - Running: ['***', 'tasks', 'run', 'weather_etl', 'transform_new_york', 'scheduled__2025-08-24T19:00:00+00:00', '--job-id', '30', '--raw', '--subdir', 'DAGS_FOLDER/weather_etl.py', '--cfg-path', '/tmp/tmpwfuqjq6p']
[2025-08-24T20:00:06.971+0000] {standard_task_runner.py:88} INFO - Job 30: Subtask transform_new_york
[2025-08-24T20:00:07.036+0000] {task_command.py:423} INFO - Running <TaskInstance: weather_etl.transform_new_york scheduled__2025-08-24T19:00:00+00:00 [running]> on host 7b1c3b0dd09a
[2025-08-24T20:00:07.113+0000] {taskinstance.py:2480} INFO - Exporting env vars: AIRFLOW_CTX_DAG_OWNER='***' AIRFLOW_CTX_DAG_ID='weather_etl' AIRFLOW_CTX_TASK_ID='transform_new_york' AIRFLOW_CTX_EXECUTION_DATE='2025-08-24T19:00:00+00:00' AIRFLOW_CTX_TRY_NUMBER='1' AIRFLOW_CTX_DAG_RUN_ID='scheduled__2025-08-24T19:00:00+00:00'
[2025-08-24T20:00:07.124+0000] {taskinstance.py:2698} ERROR - Task failed with exception
Traceback (most recent call last):
  File "/home/airflow/.local/lib/python3.8/site-packages/airflow/models/taskinstance.py", line 433, in _execute_task
    result = execute_callable(context=context, **execute_callable_kwargs)
  File "/home/airflow/.local/lib/python3.8/site-packages/airflow/operators/python.py", line 199, in execute
    return_value = self.execute_callable()
  File "/home/airflow/.local/lib/python3.8/site-packages/airflow/operators/python.py", line 216, in execute_callable
    return self.python_callable(*self.op_args, **self.op_kwargs)
  File "/opt/airflow/dags/weather_etl.py", line 74, in transform_and_load
    raise ValueError(f"Missing expected keys in API response for {city}: {data}")
ValueError: Missing expected keys in API response for New York: {'cod': 401, 'message': 'Invalid API key. Please see https://openweathermap.org/faq#error401 for more info.'}
[2025-08-24T20:00:07.141+0000] {taskinstance.py:1138} INFO - Marking task as UP_FOR_RETRY. dag_id=weather_etl, task_id=transform_new_york, execution_date=20250824T190000, start_date=20250824T200006, end_date=20250824T200007
[2025-08-24T20:00:07.152+0000] {standard_task_runner.py:107} ERROR - Failed to execute job 30 for task transform_new_york (Missing expected keys in API response for New York: {'cod': 401, 'message': 'Invalid API key. Please see https://openweathermap.org/faq#error401 for more info.'}; 203)
[2025-08-24T20:00:07.183+0000] {local_task_job_runner.py:234} INFO - Task exited with return code 1
[2025-08-24T20:00:07.203+0000] {taskinstance.py:3280} INFO - 0 downstream tasks scheduled from follow-on schedule check
