[2025-08-24T19:18:22.095+0000] {taskinstance.py:1956} INFO - Dependencies all met for dep_context=non-requeueable deps ti=<TaskInstance: weather_etl.transform_weather manual__2025-08-24T19:18:19.085849+00:00 [queued]>
[2025-08-24T19:18:22.103+0000] {taskinstance.py:1956} INFO - Dependencies all met for dep_context=requeueable deps ti=<TaskInstance: weather_etl.transform_weather manual__2025-08-24T19:18:19.085849+00:00 [queued]>
[2025-08-24T19:18:22.105+0000] {taskinstance.py:2170} INFO - Starting attempt 1 of 2
[2025-08-24T19:18:22.117+0000] {taskinstance.py:2191} INFO - Executing <Task(PythonOperator): transform_weather> on 2025-08-24 19:18:19.085849+00:00
[2025-08-24T19:18:22.122+0000] {standard_task_runner.py:60} INFO - Started process 194 to run task
[2025-08-24T19:18:22.124+0000] {standard_task_runner.py:87} INFO - Running: ['***', 'tasks', 'run', 'weather_etl', 'transform_weather', 'manual__2025-08-24T19:18:19.085849+00:00', '--job-id', '11', '--raw', '--subdir', 'DAGS_FOLDER/weather_etl.py', '--cfg-path', '/tmp/tmpg4rfeqns']
[2025-08-24T19:18:22.126+0000] {standard_task_runner.py:88} INFO - Job 11: Subtask transform_weather
[2025-08-24T19:18:22.205+0000] {task_command.py:423} INFO - Running <TaskInstance: weather_etl.transform_weather manual__2025-08-24T19:18:19.085849+00:00 [running]> on host 7b1c3b0dd09a
[2025-08-24T19:18:22.394+0000] {taskinstance.py:2480} INFO - Exporting env vars: AIRFLOW_CTX_DAG_OWNER='***' AIRFLOW_CTX_DAG_ID='weather_etl' AIRFLOW_CTX_TASK_ID='transform_weather' AIRFLOW_CTX_EXECUTION_DATE='2025-08-24T19:18:19.085849+00:00' AIRFLOW_CTX_TRY_NUMBER='1' AIRFLOW_CTX_DAG_RUN_ID='manual__2025-08-24T19:18:19.085849+00:00'
[2025-08-24T19:18:22.406+0000] {taskinstance.py:2698} ERROR - Task failed with exception
Traceback (most recent call last):
  File "/home/airflow/.local/lib/python3.8/site-packages/airflow/models/taskinstance.py", line 433, in _execute_task
    result = execute_callable(context=context, **execute_callable_kwargs)
  File "/home/airflow/.local/lib/python3.8/site-packages/airflow/operators/python.py", line 199, in execute
    return_value = self.execute_callable()
  File "/home/airflow/.local/lib/python3.8/site-packages/airflow/operators/python.py", line 216, in execute_callable
    return self.python_callable(*self.op_args, **self.op_kwargs)
  File "/opt/airflow/dags/weather_etl.py", line 37, in transform_weather
    "city": data["name"],
KeyError: 'name'
[2025-08-24T19:18:22.418+0000] {taskinstance.py:1138} INFO - Marking task as UP_FOR_RETRY. dag_id=weather_etl, task_id=transform_weather, execution_date=20250824T191819, start_date=20250824T191822, end_date=20250824T191822
[2025-08-24T19:18:22.427+0000] {standard_task_runner.py:107} ERROR - Failed to execute job 11 for task transform_weather ('name'; 194)
[2025-08-24T19:18:22.458+0000] {local_task_job_runner.py:234} INFO - Task exited with return code 1
[2025-08-24T19:18:22.476+0000] {taskinstance.py:3280} INFO - 0 downstream tasks scheduled from follow-on schedule check
