[2025-08-24T20:10:09.658+0000] {taskinstance.py:1956} INFO - Dependencies all met for dep_context=non-requeueable deps ti=<TaskInstance: weather_etl.transform_london scheduled__2025-08-24T19:00:00+00:00 [queued]>
[2025-08-24T20:10:09.669+0000] {taskinstance.py:1956} INFO - Dependencies all met for dep_context=requeueable deps ti=<TaskInstance: weather_etl.transform_london scheduled__2025-08-24T19:00:00+00:00 [queued]>
[2025-08-24T20:10:09.670+0000] {taskinstance.py:2170} INFO - Starting attempt 2 of 2
[2025-08-24T20:10:09.683+0000] {taskinstance.py:2191} INFO - Executing <Task(PythonOperator): transform_london> on 2025-08-24 19:00:00+00:00
[2025-08-24T20:10:09.689+0000] {standard_task_runner.py:60} INFO - Started process 189 to run task
[2025-08-24T20:10:09.693+0000] {standard_task_runner.py:87} INFO - Running: ['***', 'tasks', 'run', 'weather_etl', 'transform_london', 'scheduled__2025-08-24T19:00:00+00:00', '--job-id', '58', '--raw', '--subdir', 'DAGS_FOLDER/weather_etl.py', '--cfg-path', '/tmp/tmplqlrf3yx']
[2025-08-24T20:10:09.696+0000] {standard_task_runner.py:88} INFO - Job 58: Subtask transform_london
[2025-08-24T20:10:09.779+0000] {task_command.py:423} INFO - Running <TaskInstance: weather_etl.transform_london scheduled__2025-08-24T19:00:00+00:00 [running]> on host 6db65bba76ed
[2025-08-24T20:10:09.865+0000] {taskinstance.py:2480} INFO - Exporting env vars: AIRFLOW_CTX_DAG_OWNER='***' AIRFLOW_CTX_DAG_ID='weather_etl' AIRFLOW_CTX_TASK_ID='transform_london' AIRFLOW_CTX_EXECUTION_DATE='2025-08-24T19:00:00+00:00' AIRFLOW_CTX_TRY_NUMBER='2' AIRFLOW_CTX_DAG_RUN_ID='scheduled__2025-08-24T19:00:00+00:00'
[2025-08-24T20:10:09.878+0000] {taskinstance.py:2698} ERROR - Task failed with exception
Traceback (most recent call last):
  File "/home/airflow/.local/lib/python3.8/site-packages/airflow/models/taskinstance.py", line 433, in _execute_task
    result = execute_callable(context=context, **execute_callable_kwargs)
  File "/home/airflow/.local/lib/python3.8/site-packages/airflow/operators/python.py", line 199, in execute
    return_value = self.execute_callable()
  File "/home/airflow/.local/lib/python3.8/site-packages/airflow/operators/python.py", line 216, in execute_callable
    return self.python_callable(*self.op_args, **self.op_kwargs)
  File "/opt/airflow/dags/weather_etl.py", line 74, in transform_and_load
    raise ValueError(f"Missing expected keys in API response for {city}: {data}")
ValueError: Missing expected keys in API response for London: {'cod': 401, 'message': 'Invalid API key. Please see https://openweathermap.org/faq#error401 for more info.'}
[2025-08-24T20:10:09.896+0000] {taskinstance.py:1138} INFO - Marking task as FAILED. dag_id=weather_etl, task_id=transform_london, execution_date=20250824T190000, start_date=20250824T201009, end_date=20250824T201009
[2025-08-24T20:10:09.909+0000] {standard_task_runner.py:107} ERROR - Failed to execute job 58 for task transform_london (Missing expected keys in API response for London: {'cod': 401, 'message': 'Invalid API key. Please see https://openweathermap.org/faq#error401 for more info.'}; 189)
[2025-08-24T20:10:09.950+0000] {local_task_job_runner.py:234} INFO - Task exited with return code 1
[2025-08-24T20:10:09.971+0000] {taskinstance.py:3280} INFO - 0 downstream tasks scheduled from follow-on schedule check
